<?xml version="1.0"?>
<robot name="dif_bot" xmlns:xacro="http://ros.org/wiki/xacro">

  <!-- Propiedades -->
  <xacro:property name="base_width" value="0.31"/>
  <xacro:property name="base_length" value="0.42"/>
  <xacro:property name="base_height" value="0.18"/>
  <xacro:property name="wheel_radius" value="0.10"/>
  <xacro:property name="wheel_width" value="0.04"/>
  <xacro:property name="wheel_ygap" value="0.025"/>
  <xacro:property name="wheel_zoff" value="0.05"/>
  <xacro:property name="wheel_xoff" value="0.12"/>
  <xacro:property name="caster_xoff" value="0.14"/>

  <!-- Macro de inercia para caja -->
  <xacro:macro name="inertial_box" params="mass x y z">
    <inertial>
      <mass value="${mass}"/>
      <inertia ixx="${(1/12)*mass*(y*y+z*z)}"
               iyy="${(1/12)*mass*(x*x+z*z)}"
               izz="${(1/12)*mass*(x*x+y*y)}"
               ixy="0" ixz="0" iyz="0"/>
    </inertial>
  </xacro:macro>

  <!-- Macro de inercia para cilindro -->
  <xacro:macro name="inertial_cylinder" params="mass r h">
    <inertial>
      <mass value="${mass}"/>
      <inertia ixx="${(1/12)*mass*(3*r*r+h*h)}"
               iyy="${(1/12)*mass*(3*r*r+h*h)}"
               izz="${0.5*mass*r*r}"
               ixy="0" ixz="0" iyz="0"/>
    </inertial>
  </xacro:macro>

  <!-- Base -->
  <link name="base_link">
    <collision>
      <geometry>
        <box size="${base_length} ${base_width} ${base_height}"/>
      </geometry>
    </collision>

    <xacro:inertial_box mass="10.0"
                        x="${base_length}" y="${base_width}" z="${base_height}"/>
    <visual>
      <geometry>
        <box size="${base_length} ${base_width} ${base_height}"/>
      </geometry>
      <material name="Cyan">
        <color rgba="0 1.0 1.0 1.0"/>
      </material>
    </visual>
  </link>

  <!-- Footprint -->
  <link name="base_footprint"/>
  <joint name="base_joint" type="fixed">
    <parent link="base_link"/>
    <child link="base_footprint"/>
    <origin xyz="0.0 0.0 ${-(wheel_radius + wheel_zoff)}" rpy="0 0 0"/>
  </joint>

  <!-- Macro de ruedas -->
  <xacro:macro name="wheel" params="prefix x_reflect y_reflect">
    <link name="${prefix}_link">
      <collision>
        <origin xyz="0 0 0" rpy="${pi/2} 0 0"/>
        <geometry>
          <cylinder radius="${wheel_radius}" length="${wheel_width}"/>
        </geometry>
      </collision>

      <visual>
        <origin xyz="0 0 0" rpy="${pi/2} 0 0"/>
        <geometry>
          <cylinder radius="${wheel_radius}" length="${wheel_width}"/>
        </geometry>
        <material name="Gray">
          <color rgba="0.5 0.5 0.5 1.0"/>
        </material>
      </visual>

      <xacro:inertial_cylinder mass="1.0" r="${wheel_radius}" h="${wheel_width}"/>
    </link>

    <joint name="${prefix}_joint" type="continuous">
      <parent link="base_link"/>
      <child link="${prefix}_link"/>
      <origin xyz="${x_reflect*wheel_xoff} ${y_reflect*(base_width/2+wheel_ygap)} ${-wheel_zoff}" rpy="0 0 0"/>
      <axis xyz="0 1 0"/>
    </joint>
  </xacro:macro>

  <!-- Instancias -->
  <xacro:wheel prefix="drivewhl_l" x_reflect="-1" y_reflect="1"/>
  <xacro:wheel prefix="drivewhl_r" x_reflect="-1" y_reflect="-1"/>

  <!-- Caster frontal -->
  <link name="front_caster">
    <collision>
      <geometry>
        <sphere radius="${wheel_radius + wheel_zoff - (base_height/2)}"/>
      </geometry>
    </collision>

    <inertial>
      <mass value="0.5"/>
      <inertia ixx="0.001" iyy="0.001" izz="0.001" ixy="0" ixz="0" iyz="0"/>
    </inertial>

    <visual>
      <geometry>
        <sphere radius="${wheel_radius + wheel_zoff - (base_height/2)}"/>
      </geometry>
      <material name="Cyan">
        <color rgba="0 1.0 1.0 1.0"/>
      </material>
    </visual>
  </link>

  <joint name="caster_joint" type="fixed">
    <parent link="base_link"/>
    <child link="front_caster"/>
    <origin xyz="${caster_xoff} 0.0 ${-(base_height/2)}" rpy="0 0 0"/>
  </joint>

  <!-- Sensores -->
  <xacro:include filename="$(find dif_bot_description)/urdf/sensors.xacro"/>

  <!-- Gazebo DiffDrive -->
  <gazebo>
    <plugin filename="gz-sim-diff-drive-system" name="gz::sim::systems::DiffDrive">
      <left_joint>drivewhl_l_joint</left_joint>
      <right_joint>drivewhl_r_joint</right_joint>
      <wheel_separation>0.36</wheel_separation>
      <wheel_radius>0.10</wheel_radius>
      <topic>cmd_vel</topic>
      <odom_topic>odom</odom_topic>
    </plugin>

    <plugin filename="gz-sim-joint-state-publisher-system" name="gz::sim::systems::JointStatePublisher">
      <joint_name>drivewhl_l_joint</joint_name>
      <joint_name>drivewhl_r_joint</joint_name>
    </plugin>
  </gazebo>

</robot>
